Workbook

Sheet Demo
A3: RVNL | B3: 2207
A4: COCHINSHIP | B4: 657
A5: INOXWIND | B5: 4343
A6: TRENT | B6: 123
A7: HUDCO | B7: 4107
A8: GODFRYPHLP | B8: 201
A9: OFSS | B9: 92
A10: GVT&D | B10: 800
A11: IREDA | B11: 5613
A12: NETWEB | B12: 409
A13: JUBLPHARMA | B13: 791
A14: DIXON | B14: 56
... A22: POLICYBZR | B22: 425
C25: Money Allocated | D25: 15002972 | E25: Amol ji | J25: Vishal
A27: Stock | B27: targetWeight | C27: currentPrice | D27: currentQty | E27: targetQty | F27: action | G27: actionQty | H27: buy/sell price | I27: Buy/Sell Qty | J27: Price | K27: Value
A28: RVNL | B28: 0.043461605 | C28: 341.65 | D28: =Iferror(VLOOKUP(A28,$A$3:$B$22,2,0),"") -> 2207 | E28: 1857 | F28: SELL | G28: -350 | H28: 339.3114 | I28: -350 | J28: 339.3114 | K28: =I28*J28 -> -118758.99
A29: COCHINSHIP | B29: 0.044291035 | C29: 1332.1 | D29: =Iferror(VLOOKUP(A29,$A$3:$B$22,2,0),"") -> 657 | E29: 503 | F29: SELL | G29: -154 | H29: 1270.45 | I29: -154 | J29: 1270.45 | K29: =I29*J29 -> -195649.3
A30: INOXWIND | B30: 0 | C30: 170.56 | D30: =Iferror(VLOOKUP(A30,$A$3:$B$22,2,0),"") -> 4343 | E30: 0 | F30: SELL | G30: -4343 | H30: 155.4113 | I30: -4343 | J30: 155.4113 | K30: =I30*J30 -> -674951.28
A31: TRENT | B31: 0 | C31: 4990 | D31: =Iferror(VLOOKUP(A31,$A$3:$B$22,2,0),"") -> 123 | E31: 0 | F31: SELL | G31: -123 | H31: 5031.9476 | I31: -123 | J31: 5031.9476 | K31: =I31*J31 -> -618929.55
A32: HUDCO | B32: 0 | C32: 182 | D32: =Iferror(VLOOKUP(A32,$A$3:$B$22,2,0),"") -> 4107 | E32: 0 | F32: SELL | G32: -4107 | H32: 182.3782 | I32: -4107 | J32: 182.3782 | K32: =I32*J32 -> -749027.27
A33: GODFRYPHLP | B33: 0.056301762 | C33: 5305.05 | D33: =Iferror(VLOOKUP(A33,$A$3:$B$22,2,0),"") -> 201 | E33: 154 | F33: SELL | G33: -47 | H33: 5290 | I33: -47 | J33: 5290 | K33: =I33*J33 -> -248630
A34: OFSS | B34: 0 | C34: 7538 | D34: =Iferror(VLOOKUP(A34,$A$3:$B$22,2,0),"") -> 92 | E34: 0 | F34: SELL | G34: -92 | H34: 7911.05 | I34: -92 | J34: 7911.05 | K34: =I34*J34 -> -727816.6
A35: GVT&D | B35: 0.049489154 | C35: 1427.9 | D35: =Iferror(VLOOKUP(A35,$A$3:$B$22,2,0),"") -> 800 | E35: 585 | F35: SELL | G35: -215 | H35: 1387.1772 | I35: -215 | J35: 1387.1772 | K35: =I35*J35 -> -298243.1
A36: IREDA | B36: 0 | C36: 149.4 | D36: =Iferror(VLOOKUP(A36,$A$3:$B$22,2,0),"") -> 5613 | E36: 0 | F36: SELL | G36: -5613 | H36: 151.9669 | I36: -5613 | J36: 151.9669 | K36: =I36*J36 -> -852990.21
A37: NETWEB | B37: 0 | C37: 1593.5 | D37: =Iferror(VLOOKUP(A37,$A$3:$B$22,2,0),"") -> 409 | E37: 0 | F37: SELL | G37: -409 | H37: 1586.8647 | I37: -409 | J37: 1586.8647 | K37: =I37*J37 -> -649027.66
A38: JUBLPHARMA | B38: 0.041015626 | C38: 910 | D38: =Iferror(VLOOKUP(A38,$A$3:$B$22,2,0),"") -> 791 | E38: 676 | F38: SELL | G38: -115 | H38: 918.2015 | I38: -115 | J38: 918.2015 | K38: =I38*J38 -> -105593.17
A39: DIXON | B39: 0.059074288 | C39: 13888 | D39: =Iferror(VLOOKUP(A39,$A$3:$B$22,2,0),"") -> 56 | E39: 64 | F39: BUY | G39: 8 | H39: 0 | I39: 8 | J39: 13888 | K39: =I39*J39 -> 111104
... A60: VEDL | B60: 0.041242807 | C60: 445 | D60: =Iferror(VLOOKUP(A60,$A$3:$B$22,2,0),"") | E60: 1390 | F60: BUY | G60: 1390 | H60: 0 | I60: 1390 | J60: 445 | K60: =I60*J60 -> 618550
K61: =SUM(K26:K60) -> -2908.2697

Sheet TRADE_INSTRUCTIONS_HPC39_7
A1: Money Allocated | B1: 21940415
C2: Amol Ji | H2: Vishal Ji
A3: Symbol | B3: targetWeight | C3: currentPrice | D3: currentQty | E3: targetQty | F3: action | G3: actionQty | H3: Buy/Sell Qty | I3: Price | J3: Value | K3: NET QTY
A4: ANANDRATHI | B4: 0.027484492 | C4: 2955 | D4: 213 | E4: =ROUND($B$1 * B4 / C4, 0) -> 204 | F4: =IF(G4>0, "BUY", IF(G4<0, "SELL", "FLAT")) -> SELL | G4: =E4-D4 -> -9 | H4: -9 | I4: 2946.7 | J4: =I4 * H4 -> -26520.3 | K4: =D4+H4 -> 204
A5: ASTERDM | B5: 0 | C5: 544.65 | D5: 1041 | E5: =ROUND($B$1 * B5 / C5, 0) -> 0 | F5: =IF(G5>0, "BUY", IF(G5<0, "SELL", "FLAT")) -> SELL | G5: =E5-D5 -> -1041 | H5: -1041 | I5: 530.3 | J5: =I5 * H5 -> -552042.3
A6: BDL | B6: 0 | C6: 1322.3 | D6: 416 | E6: =ROUND($B$1 * B6 / C6, 0) -> 0 | F6: =IF(G6>0, "BUY", IF(G6<0, "SELL", "FLAT")) -> SELL | G6: =E6-D6 -> -416 | H6: -416 | I6: 1251.3 | J6: =I6 * H6 -> -520540.8
A7: BLUEJET | B7: 0 | C7: 422 | D7: 873 | E7: =ROUND($B$1 * B7 / C7, 0) -> 0 | F7: =IF(G7>0, "BUY", IF(G7<0, "SELL", "FLAT")) -> SELL | G7: =E7-D7 -> -873 | H7: -873 | I7: 406.35 | J7: =I7 * H7 -> -354743.55
A8: BSE | B8: 0.025145267 | C8: 2852 | D8: 325 | E8: =ROUND($B$1 * B8 / C8, 0) -> 193 | F8: =IF(G8>0, "BUY", IF(G8<0, "SELL", "FLAT")) -> SELL | G8: =E8-D8 -> -132 | H8: -132 | I8: 2852.4 | J8: =I8 * H8 -> -376516.8 | K8: =D8+H8 -> 193
A9: CEATLTD | B9: 0 | C9: 3883.9 | D9: 143 | E9: =ROUND($B$1 * B9 / C9, 0) -> 0 | F9: =IF(G9>0, "BUY", IF(G9<0, "SELL", "FLAT")) -> SELL | G9: =E9-D9 -> -143 | H9: -143 | I9: 3874.6 | J9: =I9 * H9 -> -554067.8
A10: CHOICEIN | B10: 0 | C10: 782 | D10: 879 | E10: =ROUND($B$1 * B10 / C10, 0) -> 0 | F10: =IF(G10>0, "BUY", IF(G10<0, "SELL", "FLAT")) -> SELL | G10: =E10-D10 -> -879 | H10: -879 | I10: 778.49 | J10: =I10 * H10 -> -684292.71
A11: CREDITACC | B11: 0 | C11: 1318.6 | D11: 550 | E11: =ROUND($B$1 * B11 / C11, 0) -> 0 | F11: =IF(G11>0, "BUY", IF(G11<0, "SELL", "FLAT")) -> SELL | G11: =E11-D11 -> -550 | H11: -550 | I11: 1336.4 | J11: =I11 * H11 -> -735020
A12: ECLERX | B12: 0.026040048 | C12: 4955 | D12: 159 | E12: =ROUND($B$1 * B12 / C12, 0) -> 115 | F12: =IF(G12>0, "BUY", IF(G12<0, "SELL", "FLAT")) -> SELL | G12: =E12-D12 -> -44 | H12: -44 | I12: 4461.92 | J12: =I12 * H12 -> -196324.48 | K12: =D12+H12 -> 115
A13: FORTIS | B13: 0 | C13: 864.9 | D13: 721 | E13: =ROUND($B$1 * B13 / C13, 0) -> 0 | F13: =IF(G13>0, "BUY", IF(G13<0, "SELL", "FLAT")) -> SELL | G13: =E13-D13 -> -721 | H13: -721 | I13: 854.35 | J13: =I13 * H13 -> -615986.35
A14: GPIL | B14: 0 | C14: 253 | D14: 2042 | E14: =ROUND($B$1 * B14 / C14, 0) -> 0 | F14: =IF(G14>0, "BUY", IF(G14<0, "SELL", "FLAT")) -> SELL | G14: =E14-D14 -> -2042 | H14: -2042 | I14: 255.02 | J14: =I14 * H14 -> -520750.84
A15: GRSE | B15: 0.037304193 | C15: 2545 | D15: 362 | E15: =ROUND($B$1 * B15 / C15, 0) -> 322 | F15: =IF(G15>0, "BUY", IF(G15<0, "SELL", "FLAT")) -> SELL | G15: =E15-D15 -> -40 | H15: -40 | I15: 2440.3 | J15: =I15 * H15 -> -97612 | K15: =D15+H15 -> 322
A16: GVT&D | B16: 0.03984902 | C16: 3460 | D16: 281 | E16: =ROUND($B$1 * B16 / C16, 0) -> 253 | F16: =IF(G16>0, "BUY", IF(G16<0, "SELL", "FLAT")) -> SELL | G16: =E16-D16 -> -28 | H16: -28 | I16: 3521.2 | J16: =I16 * H16 -> -98593.6 | K16: =D16+H16 -> 253
A17: INTELLECT | B17: 0 | C17: 814 | D17: 611 | E17: =ROUND($B$1 * B17 / C17, 0) -> 0 | F17: =IF(G17>0, "BUY", IF(G17<0, "SELL", "FLAT")) -> SELL | G17: =E17-D17 -> -611 | H17: -611 | I17: 776.56 | J17: =I17 * H17 -> -474478.16
A18: ITI | B18: 0 | C18: 289.4 | D18: 2475 | E18: =ROUND($B$1 * B18 / C18, 0) -> 0 | F18: =IF(G18>0, "BUY", IF(G18<0, "SELL", "FLAT")) -> SELL | G18: =E18-D18 -> -2475 | H18: -2475 | I18: 292.99 | J18: =I18 * H18 -> -725150.25
A19: JKCEMENT | B19: 0 | C19: 5620 | D19: 92 | E19: =ROUND($B$1 * B19 / C19, 0) -> 0 | F19: =IF(G19>0, "BUY", IF(G19<0, "SELL", "FLAT")) -> SELL | G19: =E19-D19 -> -92 | H19: -92 | I19: 5662.01 | J19: =I19 * H19 -> -520904.92
A20: LAURUSLABS | B20: 0.02592641 | C20: 979.5 | D20: 1025 | E20: =ROUND($B$1 * B20 / C20, 0) -> 581 | F20: =IF(G20>0, "BUY", IF(G20<0, "SELL", "FLAT")) -> SELL | G20: =E20-D20 -> -444 | H20: -444 | I20: 961.95 | J20: =I20 * H20 -> -427105.8 | K20: =D20+H20 -> 581
A21: LTF | B21: 0.031271944 | C21: 284.9 | D21: 2643 | E21: =ROUND($B$1 * B21 / C21, 0) -> 2408 | F21: =IF(G21>0, "BUY", IF(G21<0, "SELL", "FLAT")) -> SELL | G21: =E21-D21 -> -235 | H21: -235 | I21: 279.4 | J21: =I21 * H21 -> -65659 | K21: =D21+H21 -> 2408
A22: MANAPPURAM | B22: 0 | C22: 290.25 | D22: 3149 | E22: =ROUND($B$1 * B22 / C22, 0) -> 0 | F22: =IF(G22>0, "BUY", IF(G22<0, "SELL", "FLAT")) -> SELL | G22: =E22-D22 -> -3149 | H22: -3149 | I22: 286.65 | J22: =I22 * H22 -> -902660.85
A23: MAZDOCK | B23: 0 | C23: 2455 | D23: 223 | E23: =ROUND($B$1 * B23 / C23, 0) -> 0 | F23: =IF(G23>0, "BUY", IF(G23<0, "SELL", "FLAT")) -> SELL | G23: =E23-D23 -> -223 | H23: -223 | I23: 2363.32 | J23: =I23 * H23 -> -527020.36
A24: MUTHOOTFIN | B24: 0.027135146 | C24: 3644.9 | D24: 255 | E24: =ROUND($B$1 * B24 / C24, 0) -> 163 | F24: =IF(G24>0, "BUY", IF(G24<0, "SELL", "FLAT")) -> SELL | G24: =E24-D24 -> -92 | H24: -92 | I24: 3583.61 | J24: =I24 * H24 -> -329692.12 | K24: =D24+H24 -> 163
A25: NAVINFLUOR | B25: 0 | C25: 6300 | D25: 151 | E25: =ROUND($B$1 * B25 / C25, 0) -> 0 | F25: =IF(G25>0, "BUY", IF(G25<0, "SELL", "FLAT")) -> SELL | G25: =E25-D25 -> -151 | H25: -151 | I25: 6321.5 | J25: =I25 * H25 -> -954546.5
A26: PAYTM | B26: 0 | C26: 1191.3 | D26: 715 | E26: =ROUND($B$1 * B26 / C26, 0) -> 0 | F26: =IF(G26>0, "BUY", IF(G26<0, "SELL", "FLAT")) -> SELL | G26: =E26-D26 -> -715 | H26: -715 | I26: 1201.9 | J26: =I26 * H26 -> -859358.5
A27: RBLBANK | B27: 0.032662107 | C27: 304.95 | D27: 3009 | E27: =ROUND($B$1 * B27 / C27, 0) -> 2350 | F27: =IF(G27>0, "BUY", IF(G27<0, "SELL", "FLAT")) -> SELL | G27: =E27-D27 -> -659 | H27: -659 | I27: 304.05 | J27: =I27 * H27 -> -200368.95 | K27: =D27+H27 -> 2350
A28: SYRMA | B28: 0 | C28: 818 | D28: 1033 | E28: =ROUND($B$1 * B28 / C28, 0) -> 0 | F28: =IF(G28>0, "BUY", IF(G28<0, "SELL", "FLAT")) -> SELL | G28: =E28-D28 -> -1033 | H28: -1033 | I28: 830.75 | J28: =I28 * H28 -> -858164.75
A29: FORCEMOT | B29: 0.069775136 | C29: 19950 | D29: 77 | E29: =ROUND($B$1 * B29 / C29, 0) -> 77 | F29: =IF(G29>0, "BUY", IF(G29<0, "SELL", "FLAT")) -> FLAT | G29: =E29-D29 -> 0 | H29: 0 | I29: 0 | J29: =I29 * H29 -> 0 | K29: =D29+H29 -> 77
A30: POWERINDIA | B30: 0.0329124 | C30: 19715 | D30: 37 | E30: =ROUND($B$1 * B30 / C30, 0) -> 37 | F30: =IF(G30>0, "BUY", IF(G30<0, "SELL", "FLAT")) -> FLAT | G30: =E30-D30 -> 0 | H30: 0 | I30: 0 | J30: =I30 * H30 -> 0 | K30: =D30+H30 -> 37
A31: ABCAPITAL | B31: 0.033441414 | C31: 346.9 | D31: 2030 | E31: =ROUND($B$1 * B31 / C31, 0) -> 2115 | F31: =IF(G31>0, "BUY", IF(G31<0, "SELL", "FLAT")) -> BUY | G31: =E31-D31 -> 85 | H31: 85 | I31: 341.35 | J31: =I31 * H31 -> 29014.75 | K31: =D31+H31 -> 2115
A32: ASAHIINDIA | B32: 0.026371026 | C32: 989.9 | D32: 0 | E32: =ROUND($B$1 * B32 / C32, 0) -> 584 | F32: =IF(G32>0, "BUY", IF(G32<0, "SELL", "FLAT")) -> BUY | G32: =E32-D32 -> 584 | H32: 584 | I32: 948.19 | J32: =I32 * H32 -> 553742.96 | K32: =D32+H32 -> 584
A33: ASHOKLEY | B33: 0.036566441 | C33: 200 | D33: 0 | E33: =ROUND($B$1 * B33 / C33, 0) -> 4011 | F33: =IF(G33>0, "BUY", IF(G33<0, "SELL", "FLAT")) -> BUY | G33: =E33-D33 -> 4011 | H33: 4011 | I33: 199.98 | J33: =I33 * H33 -> 802119.78 | K33: =D33+H33 -> 4011
A34: AUBANK | B34: 0.026578631 | C34: 982.5 | D34: 0 | E34: =ROUND($B$1 * B34 / C34, 0) -> 594 | F34: =IF(G34>0, "BUY", IF(G34<0, "SELL", "FLAT")) -> BUY | G34: =E34-D34 -> 594 | H34: 594 | I34: 981.73 | J34: =I34 * H34 -> 583147.62 | K34: =D34+H34 -> 594
A35: BEL | B35: 0.024532372 | C35: 438.4 | D35: 0 | E35: =ROUND($B$1 * B35 / C35, 0) -> 1228 | F35: =IF(G35>0, "BUY", IF(G35<0, "SELL", "FLAT")) -> BUY | G35: =E35-D35 -> 1228 | H35: 1228 | I35: 428.05 | J35: =I35 * H35 -> 525645.4 | K35: =D35+H35 -> 1228
A36: CANBK | B36: 0.025133409 | C36: 147.4 | D36: 0 | E36: =ROUND($B$1 * B36 / C36, 0) -> 3741 | F36: =IF(G36>0, "BUY", IF(G36<0, "SELL", "FLAT")) -> BUY | G36: =E36-D36 -> 3741 | H36: 3741 | I36: 147.23 | J36: =I36 * H36 -> 550787.43 | K36: =D36+H36 -> 3741
A37: CCL | B37: 0.027084339 | C37: 984.05 | D37: 0 | E37: =ROUND($B$1 * B37 / C37, 0) -> 604 | F37: =IF(G37>0, "BUY", IF(G37<0, "SELL", "FLAT")) -> BUY | G37: =E37-D37 -> 604 | H37: 604 | I37: 981.45 | J37: =I37 * H37 -> 592795.8 | K37: =D37+H37 -> 604
A38: CHENNPETRO | B38: 0.033103854 | C38: 841.6 | D38: 0 | E38: =ROUND($B$1 * B38 / C38, 0) -> 863 | F38: =IF(G38>0, "BUY", IF(G38<0, "SELL", "FLAT")) -> BUY | G38: =E38-D38 -> 863 | H38: 863 | I38: 901.9 | J38: =I38 * H38 -> 778339.7 | K38: =D38+H38 -> 863
A39: CRAFTSMAN | B39: 0.033041918 | C39: 7699 | D39: 0 | E39: =ROUND($B$1 * B39 / C39, 0) -> 94 | F39: =IF(G39>0, "BUY", IF(G39<0, "SELL", "FLAT")) -> BUY | G39: =E39-D39 -> 94 | H39: 94 | I39: 7794.5 | J39: =I39 * H39 -> 732683 | K39: =D39+H39 -> 94
A40: CUB | B40: 0.027179632 | C40: 297.1 | D40: 0 | E40: =ROUND($B$1 * B40 / C40, 0) -> 2007 | F40: =IF(G40>0, "BUY", IF(G40<0, "SELL", "FLAT")) -> BUY | G40: =E40-D40 -> 2007 | H40: 2007 | I40: 293.46 | J40: =I40 * H40 -> 588974.22 | K40: =D40+H40 -> 2007
...

Sheet TRADE_INSTRUCTIONS_HPC39_8_1_JU
A1: Money Allocated | B1: 21729167
C2: Amol Ji | I2: Vishal Ji
A3: Symbol | B3: targetWeight | C3: currentPrice | D3: currentQty | E3: targetQty | F3: action | G3: actionQty | I3: Buy/Sell Qty | J3: Price | K3: Value | L3: NET QTY
A4: ABCAPITAL | B4: 0.027114199 | C4: 391 | D4: 2041 | E4: =ROUND($B$1 * B4 / C4, 0) -> 1507 | F4: =IF(G4>0, "BUY", IF(G4<0, "SELL", "FLAT")) -> SELL | G4: =E4-D4 -> -534 | H4: =C4*G4 -> -208794 | I4: -534 | J4: 390.45 | K4: =J4 * I4 -> -208500.3 | L4: =D4+I4 -> 1507
A5: AMBER | B5: 0 | C5: 7448.5 | D5: 126 | E5: =ROUND($B$1 * B5 / C5, 0) -> 0 | F5: =IF(G5>0, "BUY", IF(G5<0, "SELL", "FLAT")) -> SELL | G5: =E5-D5 -> -126 | H5: =C5*G5 -> -938511 | I5: -126 | J5: 7446.5 | K5: =J5 * I5 -> -938259
A6: ASHOKLEY | B6: 0.028104541 | C6: 164.1 | D6: 3792 | E6: =ROUND($B$1 * B6 / C6, 0) -> 3721 | F6: =IF(G6>0, "BUY", IF(G6<0, "SELL", "FLAT")) -> SELL | G6: =E6-D6 -> -71 | H6: =C6*G6 -> -11651.1 | I6: -71 | J6: 165.2 | K6: =J6 * I6 -> -11729.2 | L6: =D6+I6 -> 3721
A7: AUBANK | B7: 0 | C7: 1065 | D7: 736 | E7: =ROUND($B$1 * B7 / C7, 0) -> 0 | F7: =IF(G7>0, "BUY", IF(G7<0, "SELL", "FLAT")) -> SELL | G7: =E7-D7 -> -736 | H7: =C7*G7 -> -783840 | I7: -736 | J7: 1058.1 | K7: =J7 * I7 -> -778761.6
A8: BEL | B8: 0 | C8: 414.8 | D8: 974 | E8: =ROUND($B$1 * B8 / C8, 0) -> 0 | F8: =IF(G8>0, "BUY", IF(G8<0, "SELL", "FLAT")) -> SELL | G8: =E8-D8 -> -974 | H8: =C8*G8 -> -404015.2 | I8: -974 | J8: 413.25 | K8: =J8 * I8 -> -402505.5
A9: BSE | B9: 0.03198469 | C9: 3937 | D9: 225 | E9: =ROUND($B$1 * B9 / C9, 0) -> 177 | F9: =IF(G9>0, "BUY", IF(G9<0, "SELL", "FLAT")) -> SELL | G9: =E9-D9 -> -48 | H9: =C9*G9 -> -188976 | I9: -48 | J9: 3938.7 | K9: =J9 * I9 -> -189057.6 | L9: =D9+I9 -> 177
A10: CANBK | B10: 0 | C10: 127.55 | D10: 3466 | E10: =ROUND($B$1 * B10 / C10, 0) -> 0 | F10: =IF(G10>0, "BUY", IF(G10<0, "SELL", "FLAT")) -> SELL | G10: =E10-D10 -> -3466 | H10: =C10*G10 -> -442088.3 | I10: -3466 | J10: 127.03 | K10: =J10 * I10 -> -440285.98
A11: DELHIVERY | B11: 0 | C11: 510.3 | D11: 1412 | E11: =ROUND($B$1 * B11 / C11, 0) -> 0 | F11: =IF(G11>0, "BUY", IF(G11<0, "SELL", "FLAT")) -> SELL | G11: =E11-D11 -> -1412 | H11: =C11*G11 -> -720543.6 | I11: -1412 | J11: 507.95 | K11: =J11 * I11 -> -717225.4
A12: FORCEMOT | B12: 0.030901086 | C12: 18795 | D12: 60 | E12: =ROUND($B$1 * B12 / C12, 0) -> 36 | F12: =IF(G12>0, "BUY", IF(G12<0, "SELL", "FLAT")) -> SELL | G12: =E12-D12 -> -24 | H12: =C12*G12 -> -451080 | I12: -24 | J12: 18841 | K12: =J12 * I12 -> -452184 | L12: =D12+I12 -> 36
A13: GLENMARK | B13: 0 | C13: 2207.6 | D13: 219 | E13: =ROUND($B$1 * B13 / C13, 0) -> 0 | F13: =IF(G13>0, "BUY", IF(G13<0, "SELL", "FLAT")) -> SELL | G13: =E13-D13 -> -219 | H13: =C13*G13 -> -483464.4 | I13: -219 | J13: 2193.5 | K13: =J13 * I13 -> -480376.5
A14: HEROMOTOCO | B14: 0 | C14: 4808.9 | D14: 86 | E14: =ROUND($B$1 * B14 / C14, 0) -> 0 | F14: =IF(G14>0, "BUY", IF(G14<0, "SELL", "FLAT")) -> SELL | G14: =E14-D14 -> -86 | H14: =C14*G14 -> -413565.4 | I14: -86 | J14: 4814.3 | K14: =J14 * I14 -> -414029.8
A15: INDIANB | B15: 0 | C15: 815.6 | D15: 693 | E15: =ROUND($B$1 * B15 / C15, 0) -> 0 | F15: =IF(G15>0, "BUY", IF(G15<0, "SELL", "FLAT")) -> SELL | G15: =E15-D15 -> -693 | H15: =C15*G15 -> -565210.8 | I15: -693 | J15: 815.7 | K15: =J15 * I15 -> -565280.1
A16: KEI | B16: 0.026306064 | C16: 5244 | D16: 125 | E16: =ROUND($B$1 * B16 / C16, 0) -> 109 | F16: =IF(G16>0, "BUY", IF(G16<0, "SELL", "FLAT")) -> SELL | G16: =E16-D16 -> -16 | H16: =C16*G16 -> -83904 | I16: -16 | J16: 5273 | K16: =J16 * I16 -> -84368 | L16: =D16+I16 -> 109
A17: LAURUSLABS | B17: 0.044869826 | C17: 1506.1 | D17: 650 | E17: =ROUND($B$1 * B17 / C17, 0) -> 647 | F17: =IF(G17>0, "BUY", IF(G17<0, "SELL", "FLAT")) -> SELL | G17: =E17-D17 -> -3 | H17: =C17*G17 -> -4518.3 | I17: -3 | J17: 1509.9 | K17: =J17 * I17 -> -4529.7 | L17: =D17+I17 -> 647
A18: LTF | B18: 0.031981081 | C18: 314.7 | D18: 2568 | E18: =ROUND($B$1 * B18 / C18, 0) -> 2208 | F18: =IF(G18>0, "BUY", IF(G18<0, "SELL", "FLAT")) -> SELL | G18: =E18-D18 -> -360 | H18: =C18*G18 -> -113292 | I18: -360 | J18: 313.45 | K18: =J18 * I18 -> -112842 | L18: =D18+I18 -> 2208
A19: MCX | B19: 0.038759043 | C19: 3009.5 | D19: 466 | E19: =ROUND($B$1 * B19 / C19, 0) -> 280 | F19: =IF(G19>0, "BUY", IF(G19<0, "SELL", "FLAT")) -> SELL | G19: =E19-D19 -> -186 | H19: =C19*G19 -> -559767 | I19: -186 | J19: 3011 | K19: =J19 * I19 -> -560046 | L19: =D19+I19 -> 280
A20: MUTHOOTFIN | B20: 0 | C20: 2971.8 | D20: 135 | E20: =ROUND($B$1 * B20 / C20, 0) -> 0 | F20: =IF(G20>0, "BUY", IF(G20<0, "SELL", "FLAT")) -> SELL | G20: =E20-D20 -> -135 | H20: =C20*G20 -> -401193 | I20: -135 | J20: 2957.59 | K20: =J20 * I20 -> -399274.65
A21: NAM-INDIA | B21: 0.036387849 | C21: 1212.1 | D21: 701 | E21: =ROUND($B$1 * B21 / C21, 0) -> 652 | F21: =IF(G21>0, "BUY", IF(G21<0, "SELL", "FLAT")) -> SELL | G21: =E21-D21 -> -49 | H21: =C21*G21 -> -59392.9 | I21: -49 | J21: 1220.5 | K21: =J21 * I21 -> -59804.5 | L21: =D21+I21 -> 652
A22: NATIONALUM | B22: 0.037886213 | C22: 336.6 | D22: 2557 | E22: =ROUND($B$1 * B22 / C22, 0) -> 2446 | F22: =IF(G22>0, "BUY", IF(G22<0, "SELL", "FLAT")) -> SELL | G22: =E22-D22 -> -111 | H22: =C22*G22 -> -37362.6 | I22: -111 | J22: 334.95 | K22: =J22 * I22 -> -37179.45 | L22: =D22+I22 -> 2446
A23: POWERINDIA | B23: 0.044771438 | C23: 34240 | D23: 40 | E23: =ROUND($B$1 * B23 / C23, 0) -> 28 | F23: =IF(G23>0, "BUY", IF(G23<0, "SELL", "FLAT")) -> SELL | G23: =E23-D23 -> -12 | H23: =C23*G23 -> -410880 | I23: -12 | J23: 34085 | K23: =J23 * I23 -> -409020 | L23: =D23+I23 -> 28
A24: RBLBANK | B24: 0.025109634 | C24: 359.3 | D24: 2228 | E24: =ROUND($B$1 * B24 / C24, 0) -> 1519 | F24: =IF(G24>0, "BUY", IF(G24<0, "SELL", "FLAT")) -> SELL | G24: =E24-D24 -> -709 | H24: =C24*G24 -> -254743.7 | I24: -709 | J24: 356.55 | K24: =J24 * I24 -> -252793.95 | L24: =D24+I24 -> 1519
A25: SAIL | B25: 0 | C25: 169 | D25: 2653 | E25: =ROUND($B$1 * B25 / C25, 0) -> 0 | F25: =IF(G25>0, "BUY", IF(G25<0, "SELL", "FLAT")) -> SELL | G25: =E25-D25 -> -2653 | H25: =C25*G25 -> -448357 | I25: -2653 | J25: 166.71 | K25: =J25 * I25 -> -442281.63
A26: TVSMOTOR | B26: 0 | C26: 3565 | D26: 132 | E26: =ROUND($B$1 * B26 / C26, 0) -> 0 | F26: =IF(G26>0, "BUY", IF(G26<0, "SELL", "FLAT")) -> SELL | G26: =E26-D26 -> -132 | H26: =C26*G26 -> -470580 | I26: -132 | J26: 3585.6 | K26: =J26 * I26 -> -473299.2
A27: UNIONBANK | B27: 0 | C27: 174.15 | D27: 2580 | E27: =ROUND($B$1 * B27 / C27, 0) -> 0 | F27: =IF(G27>0, "BUY", IF(G27<0, "SELL", "FLAT")) -> SELL | G27: =E27-D27 -> -2580 | H27: =C27*G27 -> -449307 | I27: -2580 | J27: 174.03 | K27: =J27 * I27 -> -448997.4
A28: VEDL | B28: 0 | C28: 277.5 | D28: 821 | E28: =ROUND($B$1 * B28 / C28, 0) -> 0 | F28: =IF(G28>0, "BUY", IF(G28<0, "SELL", "FLAT")) -> SELL | G28: =E28-D28 -> -821 | H28: =C28*G28 -> -227827.5 | I28: -821 | J28: 278.15 | K28: =J28 * I28 -> -228361.15
A29: WAAREEENER | B29: 0 | C29: 2900 | D29: 145 | E29: =ROUND($B$1 * B29 / C29, 0) -> 0 | F29: =IF(G29>0, "BUY", IF(G29<0, "SELL", "FLAT")) -> SELL | G29: =E29-D29 -> -145 | H29: =C29*G29 -> -420500 | I29: -145 | J29: 2904.29 | K29: =J29 * I29 -> -421122.05
A30: ADANIENSOL | B30: 0.043851634 | C30: 1543.2 | D30: 0 | E30: =ROUND($B$1 * B30 / C30, 0) -> 617 | F30: =IF(G30>0, "BUY", IF(G30<0, "SELL", "FLAT")) -> BUY | G30: =E30-D30 -> 617 | H30: =C30*G30 -> 952154.4 | I30: 617 | J30: 1551.9 | K30: =J30 * I30 -> 957522.3 | L30: =D30+I30 -> 617
A31: ADANIENT | B31: 0.022161975 | C31: 3199.9 | D31: 0 | E31: =ROUND($B$1 * B31 / C31, 0) -> 150 | F31: =IF(G31>0, "BUY", IF(G31<0, "SELL", "FLAT")) -> BUY | G31: =E31-D31 -> 150 | H31: =C31*G31 -> 479985 | I31: 150 | J31: 3149.9 | K31: =J31 * I31 -> 472485 | L31: =D31+I31 -> 150
A32: ADANIGREEN | B32: 0.038255106 | C32: 1547.1 | D32: 0 | E32: =ROUND($B$1 * B32 / C32, 0) -> 537 | F32: =IF(G32>0, "BUY", IF(G32<0, "SELL", "FLAT")) -> BUY | G32: =E32-D32 -> 537 | H32: =C32*G32 -> 830792.7 | I32: 537 | J32: 1543.4 | K32: =J32 * I32 -> 828805.8 | L32: =D32+I32 -> 537
A33: ADANIPOWER | B33: 0.047912597 | C33: 227.6 | D33: 3996 | E33: =ROUND($B$1 * B33 / C33, 0) -> 4574 | F33: =IF(G33>0, "BUY", IF(G33<0, "SELL", "FLAT")) -> BUY | G33: =E33-D33 -> 578 | H33: =C33*G33 -> 131552.8 | I33: 578 | J33: 226.61 | K33: =J33 * I33 -> 130980.58 | L33: =D33+I33 -> 4574
A34: BHARATFORG | B34: 0.03548622 | C34: 2127.1 | D34: 318 | E34: =ROUND($B$1 * B34 / C34, 0) -> 363 | F34: =IF(G34>0, "BUY", IF(G34<0, "SELL", "FLAT")) -> BUY | G34: =E34-D34 -> 45 | H34: =C34*G34 -> 95719.5 | I34: 45 | J34: 2129 | K34: =J34 * I34 -> 95805 | L34: =D34+I34 -> 363
A35: BHEL | B35: 0.03306642 | C35: 408.25 | D35: 0 | E35: =ROUND($B$1 * B35 / C35, 0) -> 1760 | F35: =IF(G35>0, "BUY", IF(G35<0, "SELL", "FLAT")) -> BUY | G35: =E35-D35 -> 1760 | H35: =C35*G35 -> 718520 | I35: 1760 | J35: 403.13 | K35: =J35 * I35 -> 709508.8 | L35: =D35+I35 -> 1760
A36: CGPOWER | B36: 0.028147945 | C36: 969.95 | D36: 0 | E36: =ROUND($B$1 * B36 / C36, 0) -> 631 | F36: =IF(G36>0, "BUY", IF(G36<0, "SELL", "FLAT")) -> BUY | G36: =E36-D36 -> 631 | H36: =C36*G36 -> 612038.45 | I36: 631 | J36: 965.23 | K36: =J36 * I36 -> 609060.13 | L36: =D36+I36 -> 631
A37: CUMMINSIND | B37: 0.037132936 | C37: 5652 | D37: 125 | E37: =ROUND($B$1 * B37 / C37, 0) -> 143 | F37: =IF(G37>0, "BUY", IF(G37<0, "SELL", "FLAT")) -> BUY | G37: =E37-D37 -> 18 | H37: =C37*G37 -> 101736 | I37: 18 | J37: 5591 | K37: =J37 * I37 -> 100638 | L37: =D37+I37 -> 143
A38: FEDERALBNK | B38: 0.028890585 | C38: 331.6 | D38: 0 | E38: =ROUND($B$1 * B38 / C38, 0) -> 1893 | F38: =IF(G38>0, "BUY", IF(G38<0, "SELL", "FLAT")) -> BUY | G38: =E38-D38 -> 1893 | H38: =C38*G38 -> 627718.8 | I38: 1893 | J38: 330.05 | K38: =J38 * I38 -> 624784.65 | L38: =D38+I38 -> 1893
A39: GMRAIRPORT | B39: 0.024682253 | C39: 113.22 | D39: 0 | E39: =ROUND($B$1 * B39 / C39, 0) -> 4737 | F39: =IF(G39>0, "BUY", IF(G39<0, "SELL", "FLAT")) -> BUY | G39: =E39-D39 -> 4737 | H39: =C39*G39 -> 536323.14 | I39: 4737 | J39: 111.48 | K39: =J39 * I39 -> 528080.76 | L39: =D39+I39 -> 4737
A40: GVT&D | B40: 0.05096997 | C40: 4869.7 | D40: 0 | E40: =ROUND($B$1 * B40 / C40, 0) -> 227 | F40: =IF(G40>0, "BUY", IF(G40<0, "SELL", "FLAT")) -> BUY | G40: =E40-D40 -> 227 | H40: =C40*G40 -> 1105421.9 | I40: 227 | J40: 4848.98 | K40: =J40 * I40 -> 1100718.5 | L40: =D40+I40 -> 227
...

Sheet TradingInstruction_Hpc39_10_Jul
A1: Money Allocated | B1: 9632892 | D1: =sum(N4:N24) -> 0
C2: Amol Ji | I2: Vishal Ji
A3: Symbol | B3: targetWeight | C3: currentPrice | D3: currentQty | E3: targetQty | F3: action | G3: actionQty | I3: Buy/Sell Qty | J3: Price | K3: Value | L3: NET Qty
A4: BANDHANBNK | B4: 0.05 | C4: 205.19 | D4: 2416 | E4: =ROUND($B$1 * B4 / C4, 0) -> 2347 | F4: =IF(G4>0, "BUY", IF(G4<0, "SELL", "FLAT")) -> SELL | G4: =E4-D4 -> -69 | H4: =C4*G4 -> -14158.11 | I4: -69 | J4: 201.12 | K4: =J4 * I4 -> -13877.28 | L4: =D4+I4 -> 2347
A5: CREDITACC | B5: 0.05 | C5: 1549.2 | D5: 355 | E5: =ROUND($B$1 * B5 / C5, 0) -> 311 | F5: =IF(G5>0, "BUY", IF(G5<0, "SELL", "FLAT")) -> SELL | G5: =E5-D5 -> -44 | H5: =C5*G5 -> -68164.8 | I5: -44 | J5: 1558.9 | K5: =J5 * I5 -> -68591.6 | L5: =D5+I5 -> 311
A6: DEEPAKFERT | B6: 0.05 | C6: 1617.9 | D6: 314 | E6: =ROUND($B$1 * B6 / C6, 0) -> 298 | F6: =IF(G6>0, "BUY", IF(G6<0, "SELL", "FLAT")) -> SELL | G6: =E6-D6 -> -16 | H6: =C6*G6 -> -25886.4 | I6: -16 | J6: 1639.2 | K6: =J6 * I6 -> -26227.2 | L6: =D6+I6 -> 298
A7: GESHIP | B7: 0.05 | C7: 1433.6 | D7: 339 | E7: =ROUND($B$1 * B7 / C7, 0) -> 336 | F7: =IF(G7>0, "BUY", IF(G7<0, "SELL", "FLAT")) -> SELL | G7: =E7-D7 -> -3 | H7: =C7*G7 -> -4300.8 | I7: -3 | J7: 1431.7 | K7: =J7 * I7 -> -4295.1 | L7: =D7+I7 -> 336
A8: IDFCFIRSTB | B8: 0.05 | C8: 78.75 | D8: 6207 | E8: =ROUND($B$1 * B8 / C8, 0) -> 6116 | F8: =IF(G8>0, "BUY", IF(G8<0, "SELL", "FLAT")) -> SELL | G8: =E8-D8 -> -91 | H8: =C8*G8 -> -7166.25 | I8: -91 | J8: 79.52 | K8: =J8 * I8 -> -7236.32 | L8: =D8+I8 -> 6116
A9: IRB | B9: 0.05 | C9: 21.49 | D9: 23041 | E9: =ROUND($B$1 * B9 / C9, 0) -> 22412 | F9: =IF(G9>0, "BUY", IF(G9<0, "SELL", "FLAT")) -> SELL | G9: =E9-D9 -> -629 | H9: =C9*G9 -> -13517.21 | I9: -629 | J9: 21.36 | K9: =J9 * I9 -> -13435.44 | L9: =D9+I9 -> 22412
A10: LLOYDSME | B10: 0.05 | C10: 1819 | D10: 280 | E10: =ROUND($B$1 * B10 / C10, 0) -> 265 | F10: =IF(G10>0, "BUY", IF(G10<0, "SELL", "FLAT")) -> SELL | G10: =E10-D10 -> -15 | H10: =C10*G10 -> -27285 | I10: -15 | J10: 1787.1 | K10: =J10 * I10 -> -26806.5 | L10: =D10+I10 -> 265
A11: MANAPPURAM | B11: 0.05 | C11: 321.05 | D11: 1523 | E11: =ROUND($B$1 * B11 / C11, 0) -> 1500 | F11: =IF(G11>0, "BUY", IF(G11<0, "SELL", "FLAT")) -> SELL | G11: =E11-D11 -> -23 | H11: =C11*G11 -> -7384.15 | I11: -23 | J11: 329.85 | K11: =J11 * I11 -> -7586.55 | L11: =D11+I11 -> 1500
A12: MOTILALOFS | B12: 0.05 | C12: 967.7 | D12: 527 | E12: =ROUND($B$1 * B12 / C12, 0) -> 498 | F12: =IF(G12>0, "BUY", IF(G12<0, "SELL", "FLAT")) -> SELL | G12: =E12-D12 -> -29 | H12: =C12*G12 -> -28063.3 | I12: -29 | J12: 959.85 | K12: =J12 * I12 -> -27835.65 | L12: =D12+I12 -> 498
A13: OIL | B13: 0.05 | C13: 419.7 | D13: 1183 | E13: =ROUND($B$1 * B13 / C13, 0) -> 1148 | F13: =IF(G13>0, "BUY", IF(G13<0, "SELL", "FLAT")) -> SELL | G13: =E13-D13 -> -35 | H13: =C13*G13 -> -14689.5 | I13: -35 | J13: 420.95 | K13: =J13 * I13 -> -14733.25 | L13: =D13+I13 -> 1148
A14: PNB | B14: 0.05 | C14: 107.03 | D14: 4558 | E14: =ROUND($B$1 * B14 / C14, 0) -> 4500 | F14: =IF(G14>0, "BUY", IF(G14<0, "SELL", "FLAT")) -> SELL | G14: =E14-D14 -> -58 | H14: =C14*G14 -> -6207.74 | I14: -58 | J14: 105.66 | K14: =J14 * I14 -> -6128.28 | L14: =D14+I14 -> 4500
A15: REDINGTON | B15: 0.05 | C15: 277.1 | D15: 1786 | E15: =ROUND($B$1 * B15 / C15, 0) -> 1738 | F15: =IF(G15>0, "BUY", IF(G15<0, "SELL", "FLAT")) -> SELL | G15: =E15-D15 -> -48 | H15: =C15*G15 -> -13300.8 | I15: -48 | J15: 275.95 | K15: =J15 * I15 -> -13245.6 | L15: =D15+I15 -> 1738
A16: UPL | B16: 0.05 | C16: 581.45 | D16: 827 | E16: =ROUND($B$1 * B16 / C16, 0) -> 828 | F16: =IF(G16>0, "BUY", IF(G16<0, "SELL", "FLAT")) -> BUY | G16: =E16-D16 -> 1 | H16: =C16*G16 -> 581.45 | I16: 1 | J16: 611.4 | K16: =J16 * I16 -> 611.4 | L16: =D16+I16 -> 828
A17: ONGC | B17: 0 | C17: 235.07 | D17: 2036 | E17: =ROUND($B$1 * B17 / C17, 0) -> 0 | F17: =IF(G17>0, "BUY", IF(G17<0, "SELL", "FLAT")) -> SELL | G17: =E17-D17 -> -2036 | H17: =C17*G17 -> -478602.52 | I17: -2036 | J17: 238.23 | K17: =J17 * I17 -> -485036.28
A18: GPIL | B18: 0.05 | C18: 256.2 | D18: 1813 | E18: =ROUND($B$1 * B18 / C18, 0) -> 1880 | F18: =IF(G18>0, "BUY", IF(G18<0, "SELL", "FLAT")) -> BUY | G18: =E18-D18 -> 67 | H18: =C18*G18 -> 17165.4 | I18: 67 | J18: 254.95 | K18: =J18 * I18 -> 17081.65 | L18: =D18+I18 -> 1880
A19: HINDALCO | B19: 0.05 | C19: 949.7 | D19: 492 | E19: =ROUND($B$1 * B19 / C19, 0) -> 507 | F19: =IF(G19>0, "BUY", IF(G19<0, "SELL", "FLAT")) -> BUY | G19: =E19-D19 -> 15 | H19: =C19*G19 -> 14245.5 | I19: 15 | J19: 961 | K19: =J19 * I19 -> 14415 | L19: =D19+I19 -> 507
A20: JINDALSTEL | B20: 0.05 | C20: 1036.5 | D20: 441 | E20: =ROUND($B$1 * B20 / C20, 0) -> 465 | F20: =IF(G20>0, "BUY", IF(G20<0, "SELL", "FLAT")) -> BUY | G20: =E20-D20 -> 24 | H20: =C20*G20 -> 24876 | I20: 24 | J20: 1056.2 | K20: =J20 * I20 -> 25348.8 | L20: =D20+I20 -> 465
A21: NATIONALUM | B21: 0.05 | C21: 335.4 | D21: 0 | E21: =ROUND($B$1 * B21 / C21, 0) -> 1436 | F21: =IF(G21>0, "BUY", IF(G21<0, "SELL", "FLAT")) -> BUY | G21: =E21-D21 -> 1436 | H21: =C21*G21 -> 481634.4 | I21: 1436 | J21: 345.75 | K21: =J21 * I21 -> 496497 | L21: =D21+I21 -> 1436
A22: NIACL | B22: 0.05 | C22: 186.5 | D22: 2353 | E22: =ROUND($B$1 * B22 / C22, 0) -> 2583 | F22: =IF(G22>0, "BUY", IF(G22<0, "SELL", "FLAT")) -> BUY | G22: =E22-D22 -> 230 | H22: =C22*G22 -> 42895 | I22: 230 | J22: 184.75 | K22: =J22 * I22 -> 42492.5 | L22: =D22+I22 -> 2583
A23: TATASTEEL | B23: 0.05 | C23: 185.25 | D23: 2515 | E23: =ROUND($B$1 * B23 / C23, 0) -> 2600 | F23: =IF(G23>0, "BUY", IF(G23<0, "SELL", "FLAT")) -> BUY | G23: =E23-D23 -> 85 | H23: =C23*G23 -> 15746.25 | I23: 85 | J23: 190.82 | K23: =J23 * I23 -> 16219.7 | L23: =D23+I23 -> 2600
A24: VEDL | B24: 0.05 | C24: 276.95 | D24: 1636 | E24: =ROUND($B$1 * B24 / C24, 0) -> 1739 | F24: =IF(G24>0, "BUY", IF(G24<0, "SELL", "FLAT")) -> BUY | G24: =E24-D24 -> 103 | H24: =C24*G24 -> 28525.85 | I24: 103 | J24: 279.8 | K24: =J24 * I24 -> 28819.4 | L24: =D24+I24 -> 1739
A28: HPC39_10 | B28: KAPIL SIR | C28: BHAN01 | D28: BANDHANBNK | E28: INE545U01014 | F28: 2347 | G28: 174.13 | H28: 408683.1
A29: HPC39_10 | B29: KAPIL SIR | C29: CRED01 | D29: CREDITACC | E29: INE741K01010 | F29: 311 | G29: 1592.8 | H29: 495360.8
A30: HPC39_10 | B30: KAPIL SIR | C30: DEEP02 | D30: DEEPAKFERT | E30: INE501A01019 | F30: 298 | G30: 1552.8 | H30: 462734.4
A31: HPC39_10 | B31: KAPIL SIR | C31: GESH01 | D31: GESHIP | E31: INE017A01032 | F31: 336 | G31: 1350.4 | H31: 453734.4
A32: HPC39_10 | B32: KAPIL SIR | C32: GPIL01 | D32: GPIL | E32: INE177H01039 | F32: 1880 | G32: 242.4 | H32: 455712
A33: HPC39_10 | B33: KAPIL SIR | C33: HIND01 | D33: HINDALCO | E33: INE038A01020 | F33: 507 | G33: 974.45 | H33: 494046.2
A34: HPC39_10 | B34: KAPIL SIR | C34: IDFC05 | D34: IDFCFIRSTB | E34: INE092T01019 | F34: 6116 | G34: 84.68 | H34: 517902.9
A35: HPC39_10 | B35: KAPIL SIR | C35: IRB001 | D35: IRB | E35: INE821I01022 | F35: 22412 | G35: 20 | H35: 448240
A36: HPC39_10 | B36: KAPIL SIR | C36: JIND01 | D36: JINDALSTEL | E36: INE749A01030 | F36: 465 | G36: 1102.4 | H36: 512616
A37: HPC39_10 | B37: KAPIL SIR | C37: LLOY02 | D37: LLOYDSME | E37: INE281B01032 | F37: 265 | G37: 2047 | H37: 542455
A38: HPC39_10 | B38: KAPIL SIR | C38: MANA02 | D38: MANAPPURAM | E38: INE522D01027 | F38: 1500 | G38: 371.85 | H38: 557775
A39: HPC39_10 | B39: KAPIL SIR | C39: MOTI01 | D39: MOTILALOFS | E39: INE338I01027 | F39: 498 | G39: 851.95 | H39: 424271.1
... A47: HPC39_10 | B47: KAPIL SIR | C47: VEDL01 | D47: VEDL | E47: INE205A01025 | F47: 1739 | G47: 264.25 | H47: 459530.8

Sheet TradingInstruction_Hpc39_10_Sep
A1: Money Allocated | B1: 9907715
C2: Amol Ji | I2: Vishal Ji | M2: net qty
A3: Symbol | B3: targetWeight | C3: currentPrice | D3: currentQty | E3: targetQty | F3: action | G3: actionQty | I3: Buy/Sell Qty | J3: Price | K3: Value
A4: CYIENT | B4: 0.05 | C4: 1159.3 | D4: 569 | E4: =ROUND($B$1 * B4 / C4, 0) -> 427 | F4: =IF(G4>0, "BUY", IF(G4<0, "SELL", "FLAT")) -> SELL | G4: =E4-D4 -> -142 | H4: =C4*G4 -> -164620.6 | I4: -142 | J4: 1138 | K4: =J4 * I4 -> -161596 | M4: =D4+I4 -> 427
A5: JINDALSAW | B5: 0.05 | C5: 314.05 | D5: 1886 | E5: =ROUND($B$1 * B5 / C5, 0) -> 1577 | F5: =IF(G5>0, "BUY", IF(G5<0, "SELL", "FLAT")) -> SELL | G5: =E5-D5 -> -309 | H5: =C5*G5 -> -97041.45 | I5: -309 | J5: 305.5 | K5: =J5 * I5 -> -94399.5 | M5: =D5+I5 -> 1577
A6: JINDALSTEL | B6: 0.05 | C6: 1168.5 | D6: 439 | E6: =ROUND($B$1 * B6 / C6, 0) -> 424 | F6: =IF(G6>0, "BUY", IF(G6<0, "SELL", "FLAT")) -> SELL | G6: =E6-D6 -> -15 | H6: =C6*G6 -> -17527.5 | I6: -15 | J6: 1146 | K6: =J6 * I6 -> -17190 | M6: =D6+I6 -> 424
A7: PVRINOX | B7: 0.05 | C7: 1229 | D7: 432 | E7: =ROUND($B$1 * B7 / C7, 0) -> 403 | F7: =IF(G7>0, "BUY", IF(G7<0, "SELL", "FLAT")) -> SELL | G7: =E7-D7 -> -29 | H7: =C7*G7 -> -35641 | I7: -29 | J7: 1220.7 | K7: =J7 * I7 -> -35400.3 | M7: =D7+I7 -> 403
A8: GESHIP | B8: 0 | C8: 1335.3 | D8: 348 | E8: =ROUND($B$1 * B8 / C8, 0) -> 0 | F8: =IF(G8>0, "BUY", IF(G8<0, "SELL", "FLAT")) -> SELL | G8: =E8-D8 -> -348 | H8: =C8*G8 -> -464684.4 | I8: -348 | J8: 1313 | K8: =J8 * I8 -> -456924
A9: HINDALCO | B9: 0 | C9: 1028.5 | D9: 493 | E9: =ROUND($B$1 * B9 / C9, 0) -> 0 | F9: =IF(G9>0, "BUY", IF(G9<0, "SELL", "FLAT")) -> SELL | G9: =E9-D9 -> -493 | H9: =C9*G9 -> -507050.5 | I9: -493 | J9: 1005.3 | K9: =J9 * I9 -> -495612.9
A10: KEC | B10: 0 | C10: 420.45 | D10: 1020 | E10: =ROUND($B$1 * B10 / C10, 0) -> 0 | F10: =IF(G10>0, "BUY", IF(G10<0, "SELL", "FLAT")) -> SELL | G10: =E10-D10 -> -1020 | H10: =C10*G10 -> -428859 | I10: -1020 | J10: 407.6 | K10: =J10 * I10 -> -415752
A11: NATIONALUM | B11: 0 | C11: 375.8 | D11: 1338 | E11: =ROUND($B$1 * B11 / C11, 0) -> 0 | F11: =IF(G11>0, "BUY", IF(G11<0, "SELL", "FLAT")) -> SELL | G11: =E11-D11 -> -1338 | H11: =C11*G11 -> -502820.4 | I11: -1338 | J11: 369.1 | K11: =J11 * I11 -> -493855.8
A12: OIL | B12: 0 | C12: 489.95 | D12: 1083 | E12: =ROUND($B$1 * B12 / C12, 0) -> 0 | F12: =IF(G12>0, "BUY", IF(G12<0, "SELL", "FLAT")) -> SELL | G12: =E12-D12 -> -1083 | H12: =C12*G12 -> -530615.85 | I12: -1083 | J12: 488.25 | K12: =J12 * I12 -> -528774.75
A13: UPL | B13: 0 | C13: 567.5 | D13: 786 | E13: =ROUND($B$1 * B13 / C13, 0) -> 0 | F13: =IF(G13>0, "BUY", IF(G13<0, "SELL", "FLAT")) -> SELL | G13: =E13-D13 -> -786 | H13: =C13*G13 -> -446055 | I13: -786 | J13: 563.05 | K13: =J13 * I13 -> -442557.3
A14: ZEEL | B14: 0 | C14: 94.17 | D14: 4990 | E14: =ROUND($B$1 * B14 / C14, 0) -> 0 | F14: =IF(G14>0, "BUY", IF(G14<0, "SELL", "FLAT")) -> SELL | G14: =E14-D14 -> -4990 | H14: =C14*G14 -> -469908.3 | I14: -4990 | J14: 91.98 | K14: =J14 * I14 -> -458980.2
A15: IDFCFIRSTB | B15: 0.05 | C15: 85 | D15: 5766 | E15: =ROUND($B$1 * B15 / C15, 0) -> 5828 | F15: =IF(G15>0, "BUY", IF(G15<0, "SELL", "FLAT")) -> BUY | G15: =E15-D15 -> 62 | H15: =C15*G15 -> 5270 | I15: 62 | J15: 84.25 | K15: =J15 * I15 -> 5223.5 | M15: =D15+I15 -> 5828
A16: BANDHANBNK | B16: 0.05 | C16: 164 | D16: 0 | E16: =ROUND($B$1 * B16 / C16, 0) -> 3021 | F16: =IF(G16>0, "BUY", IF(G16<0, "SELL", "FLAT")) -> BUY | G16: =E16-D16 -> 3021 | H16: =C16*G16 -> 495444 | I16: 3021 | J16: 159.94 | K16: =J16 * I16 -> 483178.74 | M16: =D16+I16 -> 3021
A17: CREDITACC | B17: 0.05 | C17: 1371.1 | D17: 313 | E17: =ROUND($B$1 * B17 / C17, 0) -> 361 | F17: =IF(G17>0, "BUY", IF(G17<0, "SELL", "FLAT")) -> BUY | G17: =E17-D17 -> 48 | H17: =C17*G17 -> 65812.8 | I17: 48 | J17: 1386.9 | K17: =J17 * I17 -> 66571.2 | M17: =D17+I17 -> 361
A18: DEEPAKFERT | B18: 0.05 | C18: 1430.5 | D18: 309 | E18: =ROUND($B$1 * B18 / C18, 0) -> 346 | F18: =IF(G18>0, "BUY", IF(G18<0, "SELL", "FLAT")) -> BUY | G18: =E18-D18 -> 37 | H18: =C18*G18 -> 52928.5 | I18: 37 | J18: 1423 | K18: =J18 * I18 -> 52651 | M18: =D18+I18 -> 346
A19: ELECON | B19: 0.05 | C19: 416.9 | D19: 0 | E19: =ROUND($B$1 * B19 / C19, 0) -> 1188 | F19: =IF(G19>0, "BUY", IF(G19<0, "SELL", "FLAT")) -> BUY | G19: =E19-D19 -> 1188 | H19: =C19*G19 -> 495277.2 | I19: 1188 | J19: 410.1 | K19: =J19 * I19 -> 487198.8 | M19: =D19+I19 -> 1188
A20: GODREJPROP | B20: 0.05 | C20: 1979 | D20: 0 | E20: =ROUND($B$1 * B20 / C20, 0) -> 250 | F20: =IF(G20>0, "BUY", IF(G20<0, "SELL", "FLAT")) -> BUY | G20: =E20-D20 -> 250 | H20: =C20*G20 -> 494750 | I20: 250 | J20: 1927.5 | K20: =J20 * I20 -> 481875 | M20: =D20+I20 -> 250
A21: GPIL | B21: 0.05 | C21: 240.9 | D21: 2018 | E21: =ROUND($B$1 * B21 / C21, 0) -> 2056 | F21: =IF(G21>0, "BUY", IF(G21<0, "SELL", "FLAT")) -> BUY | G21: =E21-D21 -> 38 | H21: =C21*G21 -> 9154.2 | I21: 38 | J21: 241.65 | K21: =J21 * I21 -> 9182.7 | M21: =D21+I21 -> 2056
A22: JMFINANCIL | B22: 0.05 | C22: 129.5 | D22: 0 | E22: =ROUND($B$1 * B22 / C22, 0) -> 3825 | F22: =IF(G22>0, "BUY", IF(G22<0, "SELL", "FLAT")) -> BUY | G22: =E22-D22 -> 3825 | H22: =C22*G22 -> 495337.5 | I22: 3825 | J22: 127.08 | K22: =J22 * I22 -> 486081 | M22: =D22+I22 -> 3825
A23: LLOYDSME | B23: 0.05 | C23: 1803.7 | D23: 238 | E23: =ROUND($B$1 * B23 / C23, 0) -> 275 | F23: =IF(G23>0, "BUY", IF(G23<0, "SELL", "FLAT")) -> BUY | G23: =E23-D23 -> 37 | H23: =C23*G23 -> 66736.9 | I23: 37 | J23: 1785.9 | K23: =J23 * I23 -> 66078.3 | M23: =D23+I23 -> 275
A24: LTFOODS | B24: 0.05 | C24: 441.25 | D24: 0 | E24: =ROUND($B$1 * B24 / C24, 0) -> 1123 | F24: =IF(G24>0, "BUY", IF(G24<0, "SELL", "FLAT")) -> BUY | G24: =E24-D24 -> 1123 | H24: =C24*G24 -> 495523.75 | I24: 1123 | J24: 435.6 | K24: =J24 * I24 -> 489178.8 | M24: =D24+I24 -> 1123
A25: MANAPPURAM | B25: 0.05 | C25: 340.9 | D25: 1342 | E25: =ROUND($B$1 * B25 / C25, 0) -> 1453 | F25: =IF(G25>0, "BUY", IF(G25<0, "SELL", "FLAT")) -> BUY | G25: =E25-D25 -> 111 | H25: =C25*G25 -> 37839.9 | I25: 111 | J25: 334.05 | K25: =J25 * I25 -> 37079.55 | M25: =D25+I25 -> 1453
A26: NIACL | B26: 0.05 | C26: 189.25 | D26: 0 | E26: =ROUND($B$1 * B26 / C26, 0) -> 2618 | F26: =IF(G26>0, "BUY", IF(G26<0, "SELL", "FLAT")) -> BUY | G26: =E26-D26 -> 2618 | H26: =C26*G26 -> 495456.5 | I26: 2618 | J26: 186.95 | K26: =J26 * I26 -> 489435.1 | M26: =D26+I26 -> 2618
... A30: YESBANK | B30: 0.05 | C30: 22.2 | D30: 0 | E30: =ROUND($B$1 * B30 / C30, 0) -> 22315 | F30: =IF(G30>0, "BUY", IF(G30<0, "SELL", "FLAT")) -> BUY | G30: =E30-D30 -> 22315 | H30: =C30*G30 -> 495393 | I30: 22315 | J30: 21.9 | K30: =J30 * I30 -> 488698.5 | M30: =D30+I30 -> 22315

Sheet TRADE_INSTRUCTIONS_HPC39_5
A1: Money Allocated | B1: 13344653
C2: Amol Ji | H2: Vishal Ji
A3: Symbol | B3: targetWeight | C3: currentPrice | D3: currentQty | E3: targetQty | F3: action | G3: actionQty | H3: Buy/Sell Qty | I3: Price | J3: Value | N3: net QTy
A4: ABCAPITAL | B4: 0 | C4: 393.3 | D4: 874 | E4: =ROUND($B$1 * B4 / C4, 0) -> 0 | F4: =IF(G4>0, "BUY", IF(G4<0, "SELL", "FLAT")) -> SELL | G4: =E4-D4 -> -874 | H4: -874 | I4: 398.5 | J4: =I4 * H4 -> -348289 | L4: =C4*G4 -> -343744.2
A5: ACUTAAS | B5: 0.036292428 | C5: 3192.3 | D5: 179 | E5: =ROUND($B$1 * B5 / C5, 0) -> 152 | F5: =IF(G5>0, "BUY", IF(G5<0, "SELL", "FLAT")) -> SELL | G5: =E5-D5 -> -27 | H5: -27 | I5: 3192.7 | J5: =I5 * H5 -> -86202.9 | L5: =C5*G5 -> -86192.1 | N5: =D5+H5 -> 152
A6: ADANIPOWER | B6: 0.025580097 | C6: 203.76 | D6: 1909 | E6: =ROUND($B$1 * B6 / C6, 0) -> 1675 | F6: =IF(G6>0, "BUY", IF(G6<0, "SELL", "FLAT")) -> SELL | G6: =E6-D6 -> -234 | H6: -234 | I6: 209.04 | J6: =I6 * H6 -> -48915.36 | L6: =C6*G6 -> -47679.84 | N6: =D6+H6 -> 1675
A7: ANANDRATHI | B7: 0 | C7: 2192 | D7: 89 | E7: =ROUND($B$1 * B7 / C7, 0) -> 0 | F7: =IF(G7>0, "BUY", IF(G7<0, "SELL", "FLAT")) -> SELL | G7: =E7-D7 -> -89 | H7: -89 | I7: 2197.34 | J7: =I7 * H7 -> -195563.26 | L7: =C7*G7 -> -195088
A8: ATHERENERG | B8: 0.04669004 | C8: 1713.2 | D8: 648 | E8: =ROUND($B$1 * B8 / C8, 0) -> 364 | F8: =IF(G8>0, "BUY", IF(G8<0, "SELL", "FLAT")) -> SELL | G8: =E8-D8 -> -284 | H8: -284 | I8: 1646.91 | J8: =I8 * H8 -> -467722.44 | L8: =C8*G8 -> -486548.8 | N8: =D8+H8 -> 364
A9: BELRISE | B9: 0 | C9: 229.64 | D9: 2297 | E9: =ROUND($B$1 * B9 / C9, 0) -> 0 | F9: =IF(G9>0, "BUY", IF(G9<0, "SELL", "FLAT")) -> SELL | G9: =E9-D9 -> -2297 | H9: -2297 | I9: 236.3 | J9: =I9 * H9 -> -542781.1 | L9: =C9*G9 -> -527483.08
A10: BSE | B10: 0 | C10: 3227.8 | D10: 77 | E10: =ROUND($B$1 * B10 / C10, 0) -> 0 | F10: =IF(G10>0, "BUY", IF(G10<0, "SELL", "FLAT")) -> SELL | G10: =E10-D10 -> -77 | H10: -77 | I10: 3211.61 | J10: =I10 * H10 -> -247293.97 | L10: =C10*G10 -> -248540.6
A11: CUMMINSIND | B11: 0 | C11: 5077.5 | D11: 56 | E11: =ROUND($B$1 * B11 / C11, 0) -> 0 | F11: =IF(G11>0, "BUY", IF(G11<0, "SELL", "FLAT")) -> SELL | G11: =E11-D11 -> -56 | H11: -56 | I11: 5048.5 | J11: =I11 * H11 -> -282716 | L11: =C11*G11 -> -284340
A12: FORCEMOT | B12: 0 | C12: 17807 | D12: 21 | E12: =ROUND($B$1 * B12 / C12, 0) -> 0 | F12: =IF(G12>0, "BUY", IF(G12<0, "SELL", "FLAT")) -> SELL | G12: =E12-D12 -> -21 | H12: -21 | I12: 17708.67 | J12: =I12 * H12 -> -371882.07 | L12: =C12*G12 -> -373947
A13: GABRIEL | B13: 0 | C13: 1410.5 | D13: 337 | E13: =ROUND($B$1 * B13 / C13, 0) -> 0 | F13: =IF(G13>0, "BUY", IF(G13<0, "SELL", "FLAT")) -> SELL | G13: =E13-D13 -> -337 | H13: -337 | I13: 1385.02 | J13: =I13 * H13 -> -466751.74 | L13: =C13*G13 -> -475338.5
A14: GMDCLTD | B14: 0 | C14: 560.7 | D14: 646 | E14: =ROUND($B$1 * B14 / C14, 0) -> 0 | F14: =IF(G14>0, "BUY", IF(G14<0, "SELL", "FLAT")) -> SELL | G14: =E14-D14 -> -646 | H14: -646 | I14: 561.9 | J14: =I14 * H14 -> -362987.4 | L14: =C14*G14 -> -362212.2
A15: GVT&D | B15: 0 | C15: 4337.3 | D15: 90 | E15: =ROUND($B$1 * B15 / C15, 0) -> 0 | F15: =IF(G15>0, "BUY", IF(G15<0, "SELL", "FLAT")) -> SELL | G15: =E15-D15 -> -90 | H15: -90 | I15: 4260.12 | J15: =I15 * H15 -> -383410.8 | L15: =C15*G15 -> -390357
A16: HINDALCO | B16: 0 | C16: 1016 | D16: 298 | E16: =ROUND($B$1 * B16 / C16, 0) -> 0 | F16: =IF(G16>0, "BUY", IF(G16<0, "SELL", "FLAT")) -> SELL | G16: =E16-D16 -> -298 | H16: -298 | I16: 1012.6 | J16: =I16 * H16 -> -301754.8 | L16: =C16*G16 -> -302768
A17: KIRLOSENG | B17: 0.036238781 | C17: 2119.4 | D17: 248 | E17: =ROUND($B$1 * B17 / C17, 0) -> 228 | F17: =IF(G17>0, "BUY", IF(G17<0, "SELL", "FLAT")) -> SELL | G17: =E17-D17 -> -20 | H17: -20 | I17: 2158.3 | J17: =I17 * H17 -> -43166 | L17: =C17*G17 -> -42388 | N17: =D17+H17 -> 228
A18: LAURUSLABS | B18: 0.032586788 | C18: 1854.6 | D18: 335 | E18: =ROUND($B$1 * B18 / C18, 0) -> 234 | F18: =IF(G18>0, "BUY", IF(G18<0, "SELL", "FLAT")) -> SELL | G18: =E18-D18 -> -101 | H18: -101 | I18: 1858 | J18: =I18 * H18 -> -187658 | L18: =C18*G18 -> -187314.6 | N18: =D18+H18 -> 234
A19: LTF | B19: 0 | C19: 305.8 | D19: 1149 | E19: =ROUND($B$1 * B19 / C19, 0) -> 0 | F19: =IF(G19>0, "BUY", IF(G19<0, "SELL", "FLAT")) -> SELL | G19: =E19-D19 -> -1149 | H19: -1149 | I19: 312.35 | J19: =I19 * H19 -> -358890.15 | L19: =C19*G19 -> -351364.2
A20: MCX | B20: 0.03123421 | C20: 3279 | D20: 163 | E20: =ROUND($B$1 * B20 / C20, 0) -> 127 | F20: =IF(G20>0, "BUY", IF(G20<0, "SELL", "FLAT")) -> SELL | G20: =E20-D20 -> -36 | H20: -36 | I20: 3213.9 | J20: =I20 * H20 -> -115700.4 | L20: =C20*G20 -> -118044 | N20: =D20+H20 -> 127
A21: NAM-INDIA | B21: 0 | C21: 1173.7 | D21: 281 | E21: =ROUND($B$1 * B21 / C21, 0) -> 0 | F21: =IF(G21>0, "BUY", IF(G21<0, "SELL", "FLAT")) -> SELL | G21: =E21-D21 -> -281 | H21: -281 | I21: 1164.8 | J21: =I21 * H21 -> -327308.8 | L21: =C21*G21 -> -329809.7
A22: NATIONALUM | B22: 0.031519499 | C22: 372.05 | D22: 1181 | E22: =ROUND($B$1 * B22 / C22, 0) -> 1131 | F22: =IF(G22>0, "BUY", IF(G22<0, "SELL", "FLAT")) -> SELL | G22: =E22-D22 -> -50 | H22: -50 | I22: 375.95 | J22: =I22 * H22 -> -18797.5 | L22: =C22*G22 -> -18602.5 | N22: =D22+H22 -> 1131
A23: NETWEB | B23: 0.039707552 | C23: 5139 | D23: 111 | E23: =ROUND($B$1 * B23 / C23, 0) -> 103 | F23: =IF(G23>0, "BUY", IF(G23<0, "SELL", "FLAT")) -> SELL | G23: =E23-D23 -> -8 | H23: -8 | I23: 5117 | J23: =I23 * H23 -> -40936 | L23: =C23*G23 -> -41112 | N23: =D23+H23 -> 103
A24: POWERINDIA | B24: 0.025698313 | C24: 32690 | D24: 11 | E24: =ROUND($B$1 * B24 / C24, 0) -> 10 | F24: =IF(G24>0, "BUY", IF(G24<0, "SELL", "FLAT")) -> SELL | G24: =E24-D24 -> -1 | H24: -1 | I24: 31960 | J24: =I24 * H24 -> -31960 | L24: =C24*G24 -> -32690 | N24: =D24+H24 -> 10
A25: SCHNEIDER | B25: 0 | C25: 1173.7 | D25: 276 | E25: =ROUND($B$1 * B25 / C25, 0) -> 0 | F25: =IF(G25>0, "BUY", IF(G25<0, "SELL", "FLAT")) -> SELL | G25: =E25-D25 -> -276 | H25: -276 | I25: 1159 | J25: =I25 * H25 -> -319884 | L25: =C25*G25 -> -323941.2
A26: SYRMA | B26: 0.030806957 | C26: 1434.7 | D26: 389 | E26: =ROUND($B$1 * B26 / C26, 0) -> 287 | F26: =IF(G26>0, "BUY", IF(G26<0, "SELL", "FLAT")) -> SELL | G26: =E26-D26 -> -102 | H26: -102 | I26: 1413 | J26: =I26 * H26 -> -144126 | L26: =C26*G26 -> -146339.4 | N26: =D26+H26 -> 287
A27: USHAMART | B27: 0 | C27: 503.15 | D27: 608 | E27: =ROUND($B$1 * B27 / C27, 0) -> 0 | F27: =IF(G27>0, "BUY", IF(G27<0, "SELL", "FLAT")) -> SELL | G27: =E27-D27 -> -608 | H27: -608 | I27: 512.53 | J27: =I27 * H27 -> -311618.24 | L27: =C27*G27 -> -305915.2
A28: ADANIENSOL | B28: 0.032781468 | C28: 1385.7 | D28: 237 | E28: =ROUND($B$1 * B28 / C28, 0) -> 316 | F28: =IF(G28>0, "BUY", IF(G28<0, "SELL", "FLAT")) -> BUY | G28: =E28-D28 -> 79 | H28: 79 | I28: 1394.32 | J28: =I28 * H28 -> 110151.28 | L28: =C28*G28 -> 109470.3 | N28: =D28+H28 -> 316
A29: AEGISLOG | B29: 0.029216657 | C29: 1199.4 | D29: 0 | E29: =ROUND($B$1 * B29 / C29, 0) -> 325 | F29: =IF(G29>0, "BUY", IF(G29<0, "SELL", "FLAT")) -> BUY | G29: =E29-D29 -> 325 | H29: 325 | I29: 1257.81 | J29: =I29 * H29 -> 408788.25 | L29: =C29*G29 -> 389805 | N29: =D29+H29 -> 325
A30: APARINDS | B30: 0.036731856 | C30: 17575 | D30: 25 | E30: =ROUND($B$1 * B30 / C30, 0) -> 28 | F30: =IF(G30>0, "BUY", IF(G30<0, "SELL", "FLAT")) -> BUY | G30: =E30-D30 -> 3 | H30: 3 | I30: 17290 | J30: =I30 * H30 -> 51870 | L30: =C30*G30 -> 52725 | N30: =D30+H30 -> 28
A31: BHARATFORG | B31: 0.025617604 | C31: 2053.2 | D31: 0 | E31: =ROUND($B$1 * B31 / C31, 0) -> 167 | F31: =IF(G31>0, "BUY", IF(G31<0, "SELL", "FLAT")) -> BUY | G31: =E31-D31 -> 167 | H31: 167 | I31: 2021.45 | J31: =I31 * H31 -> 337582.15 | L31: =C31*G31 -> 342884.4 | N31: =D31+H31 -> 167
A32: BHEL | B32: 0.030655808 | C32: 425.4 | D32: 0 | E32: =ROUND($B$1 * B32 / C32, 0) -> 962 | F32: =IF(G32>0, "BUY", IF(G32<0, "SELL", "FLAT")) -> BUY | G32: =E32-D32 -> 962 | H32: 962 | I32: 426.75 | J32: =I32 * H32 -> 410533.5 | L32: =C32*G32 -> 409234.8 | N32: =D32+H32 -> 962
A33: CEMPRO | B33: 0.029699095 | C33: 1241.8 | D33: 0 | E33: =ROUND($B$1 * B33 / C33, 0) -> 319 | F33: =IF(G33>0, "BUY", IF(G33<0, "SELL", "FLAT")) -> BUY | G33: =E33-D33 -> 319 | H33: 319 | I33: 1254.5 | J33: =I33 * H33 -> 400185.5 | L33: =C33*G33 -> 396134.2 | N33: =D33+H33 -> 319
A34: CHENNPETRO | B34: 0.031236039 | C34: 1378.7 | D34: 277 | E34: =ROUND($B$1 * B34 / C34, 0) -> 302 | F34: =IF(G34>0, "BUY", IF(G34<0, "SELL", "FLAT")) -> BUY | G34: =E34-D34 -> 25 | H34: 25 | I34: 1469.3 | J34: =I34 * H34 -> 36732.5 | L34: =C34*G34 -> 34467.5 | N34: =D34+H34 -> 302
A35: CPPLUS | B35: 0.043877142 | C35: 3696.9 | D35: 0 | E35: =ROUND($B$1 * B35 / C35, 0) -> 158 | F35: =IF(G35>0, "BUY", IF(G35<0, "SELL", "FLAT")) -> BUY | G35: =E35-D35 -> 158 | H35: 158 | I35: 3678.3 | J35: =I35 * H35 -> 581171.4 | L35: =C35*G35 -> 584110.2 | N35: =D35+H35 -> 158
A36: DATAPATTNS | B36: 0.028878724 | C36: 4435.3 | D36: 0 | E36: =ROUND($B$1 * B36 / C36, 0) -> 87 | F36: =IF(G36>0, "BUY", IF(G36<0, "SELL", "FLAT")) -> BUY | G36: =E36-D36 -> 87 | H36: 87 | I36: 4584.5 | J36: =I36 * H36 -> 398851.5 | L36: =C36*G36 -> 385871.1 | N36: =D36+H36 -> 87
A37: HFCL | B37: 0.053153559 | C37: 236.64 | D37: 2420 | E37: =ROUND($B$1 * B37 / C37, 0) -> 2997 | F37: =IF(G37>0, "BUY", IF(G37<0, "SELL", "FLAT")) -> BUY | G37: =E37-D37 -> 577 | H37: 577 | I37: 226.77 | J37: =I37 * H37 -> 130846.29 | L37: =C37*G37 -> 136541.28 | N37: =D37+H37 -> 2997
A38: HINDCOPPER | B38: 0.039608979 | C38: 518.95 | D38: 958 | E38: =ROUND($B$1 * B38 / C38, 0) -> 1019 | F38: =IF(G38>0, "BUY", IF(G38<0, "SELL", "FLAT")) -> BUY | G38: =E38-D38 -> 61 | H38: 61 | I38: 525.8 | J38: =I38 * H38 -> 32073.8 | L38: =C38*G38 -> 31655.95 | N38: =D38+H38 -> 1019
A39: IDEA | B39: 0.036889353 | C39: 14.11 | D39: 32653 | E39: =ROUND($B$1 * B39 / C39, 0) -> 34888 | F39: =IF(G39>0, "BUY", IF(G39<0, "SELL", "FLAT")) -> BUY | G39: =E39-D39 -> 2235 | H39: 2235 | I39: 14.54 | J39: =I39 * H39 -> 32496.9 | L39: =C39*G39 -> 31535.85 | N39: =D39+H39 -> 34888
... A47: WELSPUNLIV | B47: 0.026246796 | C47: 197.92 | D47: 0 | E47: =ROUND($B$1 * B47 / C47, 0) -> 1770 | F47: =IF(G47>0, "BUY", IF(G47<0, "SELL", "FLAT")) -> BUY | G47: =E47-D47 -> 1770 | H47: 1770 | I47: 199.7 | J47: =I47 * H47 -> 353469 | L47: =C47*G47 -> 350318.4 | N47: =D47+H47 -> 1770

Sheet PC
A1: admin | B1: Date of Entry | C1: Index Price on entry date | D1: Current Index Price | E1: Return Index | F1: Portfolio Invested | G1: Current Value | H1: Performance | I1: Alpha
A2: HPC39_5 | B2: 45538 | C2: 23788 | D2: 22840 | E2: =(D2-C2)/C2% -> -3.9852026 | F2: =-'hpc39_5 cash ledger'!G219 -> 19981206 | G2: =hpc39_5!G153 -> 19358186 | H2: =(G2-F2)/F2% -> -3.1180272 | I2: =H2-E2 -> 0.86717539
A3: HPC39_7 | B3: 45610 | C3: 21963 | D3: 22840 | E3: =(D3-C3)/C3% -> 3.9930793
A4: HPC39_8 | B4: 45659 | C4: 22819 | D4: 22840 | E4: =(D4-C4)/C4% -> 0.092028573

Sheet TRADE_INSTRUCTIONS_HPC39_7_
A1: Money Allocated | B1: 23215067
C2: Amol Ji | I2: Vishal Ji
A3: Symbol | B3: targetWeight | C3: currentPrice | D3: currentQty | E3: targetQty | F3: action | G3: actionQty | I3: Buy/Sell Qty | J3: Price | K3: Value | L3: NET Qty
A4: ABCAPITAL | B4: 0.024730821 | C4: 350.3 | D4: 2115 | E4: =ROUND($B$1 * B4 / C4, 0) -> 1639 | F4: =IF(G4>0, "BUY", IF(G4<0, "SELL", "FLAT")) -> SELL | G4: =E4-D4 -> -476 | H4: =E4*C4 -> 574141.7 | I4: -476 | J4: 357.33 | K4: =J4 * I4 -> -170089.08 | L4: =D4+I4 -> 1639
A5: ANANDRATHI | B5: 0.031384021 | C5: 3596.2 | D5: 204 | E5: =ROUND($B$1 * B5 / C5, 0) -> 203 | F5: =IF(G5>0, "BUY", IF(G5<0, "SELL", "FLAT")) -> SELL | G5: =E5-D5 -> -1 | H5: =C5*G5 -> -3596.2 | I5: -1 | J5: 3615 | K5: =J5 * I5 -> -3615 | L5: =D5+I5 -> 203
A6: ASAHIINDIA | B6: 0 | C6: 825.25 | D6: 584 | E6: =ROUND($B$1 * B6 / C6, 0) -> 0 | F6: =IF(G6>0, "BUY", IF(G6<0, "SELL", "FLAT")) -> SELL | G6: =E6-D6 -> -584 | H6: =C6*G6 -> -481946 | I6: -584 | J6: 844 | K6: =J6 * I6 -> -492896
A7: ASHOKLEY | B7: 0 | C7: 159.2 | D7: 4011 | E7: =ROUND($B$1 * B7 / C7, 0) -> 0 | F7: =IF(G7>0, "BUY", IF(G7<0, "SELL", "FLAT")) -> SELL | G7: =E7-D7 -> -4011 | H7: =C7*G7 -> -638551.2 | I7: -4011 | J7: 159.1 | K7: =J7 * I7 -> -638150.1
A8: AUBANK | B8: 0 | C8: 1019.6 | D8: 594 | E8: =ROUND($B$1 * B8 / C8, 0) -> 0 | F8: =IF(G8>0, "BUY", IF(G8<0, "SELL", "FLAT")) -> SELL | G8: =E8-D8 -> -594 | H8: =C8*G8 -> -605642.4 | I8: -594 | J8: 1009.9 | K8: =J8 * I8 -> -599880.6
A9: BEL | B9: 0 | C9: 434.15 | D9: 1228 | E9: =ROUND($B$1 * B9 / C9, 0) -> 0 | F9: =IF(G9>0, "BUY", IF(G9<0, "SELL", "FLAT")) -> SELL | G9: =E9-D9 -> -1228 | H9: =C9*G9 -> -533136.2 | I9: -1228 | J9: 430.82 | K9: =J9 * I9 -> -529046.96
A10: BSE | B10: 0.027158817 | C10: 3680.6 | D10: 193 | E10: =ROUND($B$1 * B10 / C10, 0) -> 171 | F10: =IF(G10>0, "BUY", IF(G10<0, "SELL", "FLAT")) -> SELL | G10: =E10-D10 -> -22 | H10: =C10*G10 -> -80973.2 | I10: -22 | J10: 3703 | K10: =J10 * I10 -> -81466 | L10: =D10+I10 -> 171
A11: CANBK | B11: 0 | C11: 134.96 | D11: 3741 | E11: =ROUND($B$1 * B11 / C11, 0) -> 0 | F11: =IF(G11>0, "BUY", IF(G11<0, "SELL", "FLAT")) -> SELL | G11: =E11-D11 -> -3741 | H11: =C11*G11 -> -504885.36 | I11: -3741 | J11: 134.2 | K11: =J11 * I11 -> -502042.2
A12: CHENNPETRO | B12: 0.02921823 | C12: 1107 | D12: 863 | E12: =ROUND($B$1 * B12 / C12, 0) -> 613 | F12: =IF(G12>0, "BUY", IF(G12<0, "SELL", "FLAT")) -> SELL | G12: =E12-D12 -> -250 | H12: =C12*G12 -> -276750 | I12: -250 | J12: 1112.2 | K12: =J12 * I12 -> -278050 | L12: =D12+I12 -> 613
A13: CRAFTSMAN | B13: 0 | C13: 7647.5 | D13: 94 | E13: =ROUND($B$1 * B13 / C13, 0) -> 0 | F13: =IF(G13>0, "BUY", IF(G13<0, "SELL", "FLAT")) -> SELL | G13: =E13-D13 -> -94 | H13: =C13*G13 -> -718865 | I13: -94 | J13: 7641.65 | K13: =J13 * I13 -> -718315.1
A14: CUB | B14: 0 | C14: 270.5 | D14: 2007 | E14: =ROUND($B$1 * B14 / C14, 0) -> 0 | F14: =IF(G14>0, "BUY", IF(G14<0, "SELL", "FLAT")) -> SELL | G14: =E14-D14 -> -2007 | H14: =C14*G14 -> -542893.5 | I14: -2007 | J14: 271 | K14: =J14 * I14 -> -543897
A15: ECLERX | B15: 0 | C15: 1391 | D15: 230 | E15: =ROUND($B$1 * B15 / C15, 0) -> 0 | F15: =IF(G15>0, "BUY", IF(G15<0, "SELL", "FLAT")) -> SELL | G15: =E15-D15 -> -230 | H15: =C15*G15 -> -319930 | I15: -230 | J15: 1454.12 | K15: =J15 * I15 -> -334447.6
A16: FORCEMOT | B16: 0.03771921 | C16: 19143 | D16: 77 | E16: =ROUND($B$1 * B16 / C16, 0) -> 46 | F16: =IF(G16>0, "BUY", IF(G16<0, "SELL", "FLAT")) -> SELL | G16: =E16-D16 -> -31 | H16: =C16*G16 -> -593433 | I16: -31 | J16: 19235.19 | K16: =J16 * I16 -> -596290.89 | L16: =D16+I16 -> 46
A17: GMDCLTD | B17: 0.043414202 | C17: 713.4 | D17: 1440 | E17: =ROUND($B$1 * B17 / C17, 0) -> 1413 | F17: =IF(G17>0, "BUY", IF(G17<0, "SELL", "FLAT")) -> SELL | G17: =E17-D17 -> -27 | H17: =C17*G17 -> -19261.8 | I17: -27 | J17: 737.6 | K17: =J17 * I17 -> -19915.2 | L17: =D17+I17 -> 1413
A18: GRSE | B18: 0.025909777 | C18: 2773.7 | D18: 322 | E18: =ROUND($B$1 * B18 / C18, 0) -> 217 | F18: =IF(G18>0, "BUY", IF(G18<0, "SELL", "FLAT")) -> SELL | G18: =E18-D18 -> -105 | H18: =C18*G18 -> -291238.5 | I18: -105 | J18: 2797 | K18: =J18 * I18 -> -293685 | L18: =D18+I18 -> 217
A19: GVT&D | B19: 0.04550268 | C19: 4476.2 | D19: 253 | E19: =ROUND($B$1 * B19 / C19, 0) -> 236 | F19: =IF(G19>0, "BUY", IF(G19<0, "SELL", "FLAT")) -> SELL | G19: =E19-D19 -> -17 | H19: =C19*G19 -> -76095.4 | I19: -17 | J19: 4565 | K19: =J19 * I19 -> -77605 | L19: =D19+I19 -> 236
A20: HINDCOPPER | B20: 0.043811124 | C20: 529.55 | D20: 1979 | E20: =ROUND($B$1 * B20 / C20, 0) -> 1921 | F20: =IF(G20>0, "BUY", IF(G20<0, "SELL", "FLAT")) -> SELL | G20: =E20-D20 -> -58 | H20: =C20*G20 -> -30713.9 | I20: -58 | J20: 533.55 | K20: =J20 * I20 -> -30945.9 | L20: =D20+I20 -> 1921
A21: INDIACEM | B21: 0 | C21: 386 | D21: 1530 | E21: =ROUND($B$1 * B21 / C21, 0) -> 0 | F21: =IF(G21>0, "BUY", IF(G21<0, "SELL", "FLAT")) -> SELL | G21: =E21-D21 -> -1530 | H21: =C21*G21 -> -590580 | I21: -1530 | J21: 393.3 | K21: =J21 * I21 -> -601749
A22: JKTYRE | B22: 0 | C22: 403.1 | D22: 1210 | E22: =ROUND($B$1 * B22 / C22, 0) -> 0 | F22: =IF(G22>0, "BUY", IF(G22<0, "SELL", "FLAT")) -> SELL | G22: =E22-D22 -> -1210 | H22: =C22*G22 -> -487751 | I22: -1210 | J22: 400.85 | K22: =J22 * I22 -> -485028.5
A23: LAURUSLABS | B23: 0.02537362 | C23: 1163.1 | D23: 581 | E23: =ROUND($B$1 * B23 / C23, 0) -> 506 | F23: =IF(G23>0, "BUY", IF(G23<0, "SELL", "FLAT")) -> SELL | G23: =E23-D23 -> -75 | H23: =C23*G23 -> -87232.5 | I23: -75 | J23: 1169.5 | K23: =J23 * I23 -> -87712.5 | L23: =D23+I23 -> 506
A24: LTF | B24: 0 | C24: 284.2 | D24: 2408 | E24: =ROUND($B$1 * B24 / C24, 0) -> 0 | F24: =IF(G24>0, "BUY", IF(G24<0, "SELL", "FLAT")) -> SELL | G24: =E24-D24 -> -2408 | H24: =C24*G24 -> -684353.6 | I24: -2408 | J24: 284.85 | K24: =J24 * I24 -> -685918.8
A25: MCX | B25: 0.040970445 | C25: 2904.9 | D25: 372 | E25: =ROUND($B$1 * B25 / C25, 0) -> 327 | F25: =IF(G25>0, "BUY", IF(G25<0, "SELL", "FLAT")) -> SELL | G25: =E25-D25 -> -45 | H25: =C25*G25 -> -130720.5 | I25: -45 | J25: 2903.52 | K25: =J25 * I25 -> -130658.4 | L25: =D25+I25 -> 327
A26: MUTHOOTFIN | B26: 0 | C26: 3461.2 | D26: 163 | E26: =ROUND($B$1 * B26 / C26, 0) -> 0 | F26: =IF(G26>0, "BUY", IF(G26<0, "SELL", "FLAT")) -> SELL | G26: =E26-D26 -> -163 | H26: =C26*G26 -> -564175.6 | I26: -163 | J26: 3399.47 | K26: =J26 * I26 -> -554113.61
A27: NETWEB | B27: 0.045712877 | C27: 3910 | D27: 292 | E27: =ROUND($B$1 * B27 / C27, 0) -> 271 | F27: =IF(G27>0, "BUY", IF(G27<0, "SELL", "FLAT")) -> SELL | G27: =E27-D27 -> -21 | H27: =C27*G27 -> -82110 | I27: -21 | J27: 4071.3 | K27: =J27 * I27 -> -85497.3 | L27: =D27+I27 -> 271
A28: POWERINDIA | B28: 0.04043882 | C28: 33605 | D28: 37 | E28: =ROUND($B$1 * B28 / C28, 0) -> 28 | F28: =IF(G28>0, "BUY", IF(G28<0, "SELL", "FLAT")) -> SELL | G28: =E28-D28 -> -9 | H28: =C28*G28 -> -302445 | I28: -9 | J28: 34025 | K28: =J28 * I28 -> -306225 | L28: =D28+I28 -> 28
A29: RBLBANK | B29: 0 | C29: 330.15 | D29: 2350 | E29: =ROUND($B$1 * B29 / C29, 0) -> 0 | F29: =IF(G29>0, "BUY", IF(G29<0, "SELL", "FLAT")) -> SELL | G29: =E29-D29 -> -2350 | H29: =C29*G29 -> -775852.5 | I29: -2350 | J29: 327.5 | K29: =J29 * I29 -> -769625
A30: SHRIRAMFIN | B30: 0 | C30: 949.15 | D30: 660 | E30: =ROUND($B$1 * B30 / C30, 0) -> 0 | F30: =IF(G30>0, "BUY", IF(G30<0, "SELL", "FLAT")) -> SELL | G30: =E30-D30 -> -660 | H30: =C30*G30 -> -626439 | I30: -660 | J30: 945.5 | K30: =J30 * I30 -> -624030
A31: UNIONBANK | B31: 0 | C31: 164.43 | D31: 3104 | E31: =ROUND($B$1 * B31 / C31, 0) -> 0 | F31: =IF(G31>0, "BUY", IF(G31<0, "SELL", "FLAT")) -> SELL | G31: =E31-D31 -> -3104 | H31: =C31*G31 -> -510390.72 | I31: -3104 | J31: 162.81 | K31: =J31 * I31 -> -505362.24
A32: ABDL | B32: 0.026826719 | C32: 533.8 | D32: 0 | E32: =ROUND($B$1 * B32 / C32, 0) -> 1167 | F32: =IF(G32>0, "BUY", IF(G32<0, "SELL", "FLAT")) -> BUY | G32: =E32-D32 -> 1167 | H32: =C32*G32 -> 622944.6 | I32: 1167 | J32: 540.23 | K32: =J32 * I32 -> 630448.41 | L32: =D32+I32 -> 1167
A33: ADANIPOWER | B33: 0.032999837 | C33: 227.46 | D33: 0 | E33: =ROUND($B$1 * B33 / C33, 0) -> 3368 | F33: =IF(G33>0, "BUY", IF(G33<0, "SELL", "FLAT")) -> BUY | G33: =E33-D33 -> 3368 | H33: =C33*G33 -> 766085.28 | I33: 3368 | J33: 233 | K33: =J33 * I33 -> 784744 | L33: =D33+I33 -> 3368
A34: APARINDS | B34: 0.038299818 | C34: 12359 | D34: 0 | E34: =ROUND($B$1 * B34 / C34, 0) -> 72 | F34: =IF(G34>0, "BUY", IF(G34<0, "SELL", "FLAT")) -> BUY | G34: =E34-D34 -> 72 | H34: =C34*G34 -> 889848 | I34: 72 | J34: 12685 | K34: =J34 * I34 -> 913320 | L34: =D34+I34 -> 72
A35: CCL | B35: 0.031333595 | C35: 1171 | D35: 604 | E35: =ROUND($B$1 * B35 / C35, 0) -> 621 | F35: =IF(G35>0, "BUY", IF(G35<0, "SELL", "FLAT")) -> BUY | G35: =E35-D35 -> 17 | H35: =C35*G35 -> 19907 | I35: 17 | J35: 1167.4 | K35: =J35 * I35 -> 19845.8 | L35: =D35+I35 -> 621
A36: CUMMINSIND | B36: 0.026590514 | C36: 5283.5 | D36: 0 | E36: =ROUND($B$1 * B36 / C36, 0) -> 117 | F36: =IF(G36>0, "BUY", IF(G36<0, "SELL", "FLAT")) -> BUY | G36: =E36-D36 -> 117 | H36: =C36*G36 -> 618169.5 | I36: 117 | J36: 5252.48 | K36: =J36 * I36 -> 614540.16 | L36: =D36+I36 -> 117
A37: DATAPATTNS | B37: 0.030897347 | C37: 4004.1 | D37: 0 | E37: =ROUND($B$1 * B37 / C37, 0) -> 179 | F37: =IF(G37>0, "BUY", IF(G37<0, "SELL", "FLAT")) -> BUY | G37: =E37-D37 -> 179 | H37: =C37*G37 -> 716733.9 | I37: 179 | J37: 4131.13 | K37: =J37 * I37 -> 739472.27 | L37: =D37+I37 -> 179
A38: GABRIEL | B38: 0.03513398 | C38: 1028.6 | D38: 0 | E38: =ROUND($B$1 * B38 / C38, 0) -> 793 | F38: =IF(G38>0, "BUY", IF(G38<0, "SELL", "FLAT")) -> BUY | G38: =E38-D38 -> 793 | H38: =C38*G38 -> 815679.8 | I38: 793 | J38: 1045.4 | K38: =J38 * I38 -> 829002.2 | L38: =D38+I38 -> 793
A39: GALLANTT | B39: 0.033116715 | C39: 869.5 | D39: 0 | E39: =ROUND($B$1 * B39 / C39, 0) -> 884 | F39: =IF(G39>0, "BUY", IF(G39<0, "SELL", "FLAT")) -> BUY | G39: =E39-D39 -> 884 | H39: =C39*G39 -> 768638 | I39: 884 | J39: 879.54 | K39: =J39 * I39 -> 777513.36 | L39: =D39+I39 -> 884
A40: GESHIP | B40: 0.024550027 | C40: 1531 | D40: 0 | E40: =ROUND($B$1 * B40 / C40, 0) -> 372 | F40: =IF(G40>0, "BUY", IF(G40<0, "SELL", "FLAT")) -> BUY | G40: =E40-D40 -> 372 | H40: =C40*G40 -> 569532 | I40: 372 | J40: 1526.7 | K40: =J40 * I40 -> 567932.4 | L40: =D40+I40 -> 372
...

Sheet Sheet44
A1: Client Code | B1: Name | C1: Scrip Code | D1: Scrip Name | E1: ISIN Code | F1: Stock | G1: Close Rate | H1: Stk.Value Credit | I1: Stk.Value Debit | J1: Variance | K1: Stock Val
A2: HPC39_5 | B2: AMOL | C2: ABCA01 | D2: ABCAPITAL | E2: INE674K01013 | F2: 874 | G2: 405.55 | H2: 354450.7 | I2: 0 | J2: 82.74 | K2: 293272.5
A3: HPC39_5 | B3: AMOL | C3: ACUT01 | D3: ACUTAAS | F3: 179 | G3: 3281.6 | H3: 587406.4 | I3: 0 | J3: 0 | K3: 0
A4: HPC39_5 | B4: AMOL | C4: ADAN06 | D4: ADANIENSOL | E4: INE931S01010 | F4: 237 | G4: 1581.4 | H4: 374791.8 | I4: 0 | J4: 78.46 | K4: 294061.6
A5: HPC39_5 | B5: AMOL | C5: ADAN01 | D5: ADANIPOWER | E5: INE814H01029 | F5: 1909 | G5: 212.63 | H5: 405910.7 | I5: 0 | J5: 79.3 | K5: 321887.2
A6: HPC39_5 | B6: AMOL | C6: ANAN02 | D6: ANANDRATHI | E6: INE463V01026 | F6: 89 | G6: 2213.4 | H6: 196992.6 | I6: 0 | J6: 85.9 | K6: 169216.6
A7: HPC39_5 | B7: AMOL | C7: APAR01 | D7: APARINDS | E7: INE372A01015 | F7: 25 | G7: 17803 | H7: 445075 | I7: 0 | J7: 76.82 | K7: 341906.6
A8: HPC39_5 | B8: AMOL | C8: ATHE01 | D8: ATHERENERG | F8: 648 | G8: 1616.3 | H8: 1047362 | I8: 0 | J8: 0 | K8: 0
A9: HPC39_5 | B9: AMOL | C9: BELR01 | D9: BELRISE | F9: 2297 | G9: 229.87 | H9: 528011.4 | I9: 0 | J9: 0 | K9: 0
A10: HPC39_5 | B10: AMOL | C10: BSE001 | D10: BSE | E10: INE118H01025 | F10: 77 | G10: 3405 | H10: 262185 | I10: 0 | J10: 77.95 | K10: 204373.2
A11: HPC39_5 | B11: AMOL | C11: CHEN01 | D11: CHENNPETRO | E11: INE178A01016 | F11: 277 | G11: 1341.1 | H11: 371484.7 | I11: 0 | J11: 76.24 | K11: 283219.9
A12: HPC39_5 | B12: AMOL | C12: CUMM01 | D12: CUMMINSIND | E12: INE298A01020 | F12: 56 | G12: 5193 | H12: 290808 | I12: 0 | J12: 84.27 | K12: 245063.9
A13: HPC39_5 | B13: AMOL | C13: FORC01 | D13: FORCEMOT | E13: INE451A01017 | F13: 21 | G13: 17370 | H13: 364770 | I13: 0 | J13: 74.89 | K13: 273176.3
